Workbook

Sheet Financial data
A1: Invoice_ID | B1: Date | C1: Customer | D1: Region | E1: Category | F1: Product | G1: Quantity | H1: Unit_Price | I1: Revenue | J1: COGS | K1: Gross_Profit | L1: Operating_Expense | M1: EBITDA | N1: Tax | O1: Net_Profit | P1: Budget_Revenue | Q1: Budget_Expense
A2: INV-00058 | B2: 45748 | C2: Customer 047 | D2: Tamil Nadu | E2: Home Care | F2: Laundry Detergent | G2: 2 | H2: 300.99 | I2: 601.98 | J2: 368.12 | K2: 233.87 | L2: 59.99 | M2: 173.88 | N2: 32.42 | O2: 141.46 | P2: 618.78 | Q2: 56.07
A3: INV-00542 | B3: 45748 | C3: Customer 051 | D3: Tamil Nadu | E3: Personal Care | F3: Face Wash | G3: 4 | H3: 169.74 | I3: 678.97 | J3: 380.38 | K3: 298.59 | L3: 69.72 | M3: 228.87 | N3: 53.94 | O3: 174.93 | P3: 650.62 | Q3: 72.22
A4: INV-01067 | B4: 45748 | C4: Customer 030 | D4: Tamil Nadu | E4: Food & Beverages | F4: Instant Noodles | G4: 5 | H4: 64.78 | I4: 323.91 | J4: 228.7 | K4: 95.21 | L4: 34.46 | M4: 60.76 | N4: 12.37 | O4: 48.38 | P4: 337.43 | Q4: 37.25
A5: INV-01354 | B5: 45748 | C5: Customer 115 | D5: Kerala | E5: Personal Care | F5: Body Lotion | G5: 15 | H5: 259.54 | I5: 3893.15 | J5: 2316.02 | K5: 1577.13 | L5: 416.84 | M5: 1160.29 | N5: 281.4 | O5: 878.89 | P5: 3674.65 | Q5: 393.95
A6: INV-01788 | B6: 45748 | C6: Customer 027 | D6: Karnataka | E6: Personal Care | F6: Face Wash | G6: 15 | H6: 172.66 | I6: 2589.84 | J6: 1537.45 | K6: 1052.39 | L6: 238.24 | M6: 814.15 | N6: 157.26 | O6: 656.88 | P6: 2669.02 | Q6: 256.48
A7: INV-01868 | B7: 45748 | C7: Customer 027 | D7: Karnataka | E7: Electronics Accessories | F7: Phone Charger | G7: 6 | H7: 700.34 | I7: 4202.04 | J7: 3016.27 | K7: 1185.76 | L7: 429.89 | M7: 755.87 | N7: 180.27 | O7: 575.6 | P7: 4527.43 | Q7: 468.59
A8: INV-02055 | B8: 45748 | C8: Customer 094 | D8: Karnataka | E8: Personal Care | F8: Body Lotion | G8: 11 | H8: 241.65 | I8: 2658.15 | J8: 1586.97 | K8: 1071.18 | L8: 314.37 | M8: 756.81 | N8: 172.07 | O8: 584.74 | P8: 2811.89 | Q8: 319.52
A9: INV-02751 | B9: 45748 | C9: Customer 024 | D9: Karnataka | E9: Home Care | F9: Floor Cleaner | G9: 14 | H9: 225.93 | I9: 3163 | J9: 2011.58 | K9: 1151.42 | L9: 291.64 | M9: 859.79 | N9: 181.8 | O9: 677.99 | P9: 3337.09 | Q9: 319.02
A10: INV-02953 | B10: 45748 | C10: Customer 002 | D10: Kerala | E10: Food & Beverages | F10: Fruit Juice | G10: 20 | H10: 123.04 | I10: 2460.89 | J10: 1640.17 | K10: 820.73 | L10: 257.1 | M10: 563.63 | N10: 112.18 | O10: 451.45 | P10: 2449.4 | Q10: 239.6
A11: INV-03620 | B11: 45748 | C11: Customer 055 | D11: Karnataka | E11: Home Care | F11: Floor Cleaner | G11: 3 | H11: 226.32 | I11: 678.95 | J11: 405.03 | K11: 273.92 | L11: 75.45 | M11: 198.47 | N11: 36.09 | O11: 162.38 | P11: 672.1 | Q11: 75.22
A12: INV-03628 | B12: 45748 | C12: Customer 109 | D12: Kerala | E12: Home Care | F12: Laundry Detergent | G12: 14 | H12: 308.7 | I12: 4321.84 | J12: 2778.7 | K12: 1543.14 | L12: 480.41 | M12: 1062.73 | N12: 191.88 | O12: 870.85 | P12: 4364.32 | Q12: 477.81
A13: INV-04008 | B13: 45748 | C13: Customer 096 | D13: Karnataka | E13: Food & Beverages | F13: Fruit Juice | G13: 9 | H13: 128.05 | I13: 1152.43 | J13: 787.52 | K13: 364.9 | L13: 137.06 | M13: 227.85 | N13: 47.42 | O13: 180.43 | P13: 1094.92 | Q13: 139.75
... A8001: INV-07312 | B8001: 46112 | C8001: Customer 098 | D8001: Kerala | E8001: Food & Beverages | F8001: Instant Noodles | G8001: 4 | H8001: 72.53 | I8001: 290.13 | J8001: 198.21 | K8001: 91.92 | L8001: 31.86 | M8001: 60.06 | N8001: 14.57 | O8001: 45.49 | P8001: 278.84 | Q8001: 34.66

Sheet Financial Analysis
A1: FINANCIAL KPI | B1: VALUE | I1: MONTH | J1: REVENUE | K1: NET PROFIT | L1: NET PROFIT MARGIN%
A2: Total Revenue | B2: =SUM(financialdata[Revenue]) -> 24539829 | I2: 45748 | J2: =SUMIFS(financialdata[Revenue],financialdata[Date],">="&I2,financialdata[Date],"<"&EDATE('Financial Analysis'!I2,1)) -> 1998337.2 | K2: =SUMIFS(financialdata[Net_Profit],financialdata[Date],">="&'Financial Analysis'!I2,financialdata[Date],"<"&EDATE('Financial Analysis'!I2,1)) -> 347459.84 | L2: =K2/J2 -> 0.17387448
A3: Total Cogs | B3: =SUM(financialdata[COGS]) -> 16669210 | I3: =EDATE(I2,1) -> 45778 | J3: =SUMIFS(financialdata[Revenue],financialdata[Date],">="&I3,financialdata[Date],"<"&EDATE('Financial Analysis'!I3,1)) -> 1842819.7 | K3: =SUMIFS(financialdata[Net_Profit],financialdata[Date],">="&'Financial Analysis'!I3,financialdata[Date],"<"&EDATE('Financial Analysis'!I3,1)) -> 321068.65 | L3: =K3/J3 -> 0.17422684
A4: Gross profit | B4: =SUM(financialdata[Gross_Profit]) -> 7870618.4 | I4: =EDATE(I3,1) -> 45809 | J4: =SUMIFS(financialdata[Revenue],financialdata[Date],">="&I4,financialdata[Date],"<"&EDATE('Financial Analysis'!I4,1)) -> 1890702 | K4: =SUMIFS(financialdata[Net_Profit],financialdata[Date],">="&'Financial Analysis'!I4,financialdata[Date],"<"&EDATE('Financial Analysis'!I4,1)) -> 325118.33 | L4: =K4/J4 -> 0.17195642
A5: Gross profit margin % | B5: =B4/B2 -> 0.32072833 | I5: =EDATE(I4,1) -> 45839 | J5: =SUMIFS(financialdata[Revenue],financialdata[Date],">="&I5,financialdata[Date],"<"&EDATE('Financial Analysis'!I5,1)) -> 1921643 | K5: =SUMIFS(financialdata[Net_Profit],financialdata[Date],">="&'Financial Analysis'!I5,financialdata[Date],"<"&EDATE('Financial Analysis'!I5,1)) -> 332674.07 | L5: =K5/J5 -> 0.1731196
A6: Operating Expenses | B6: =SUM(financialdata[Operating_Expense]) -> 2652509.5 | I6: =EDATE(I5,1) -> 45870 | J6: =SUMIFS(financialdata[Revenue],financialdata[Date],">="&I6,financialdata[Date],"<"&EDATE('Financial Analysis'!I6,1)) -> 2156635.5 | K6: =SUMIFS(financialdata[Net_Profit],financialdata[Date],">="&'Financial Analysis'!I6,financialdata[Date],"<"&EDATE('Financial Analysis'!I6,1)) -> 310349 | L6: =K6/J6 -> 0.14390424
A7: EBITDA | B7: =SUM(financialdata[EBITDA]) -> 5218108.7 | I7: =EDATE(I6,1) -> 45901 | J7: =SUMIFS(financialdata[Revenue],financialdata[Date],">="&I7,financialdata[Date],"<"&EDATE('Financial Analysis'!I7,1)) -> 2019879.5 | K7: =SUMIFS(financialdata[Net_Profit],financialdata[Date],">="&'Financial Analysis'!I7,financialdata[Date],"<"&EDATE('Financial Analysis'!I7,1)) -> 291420.31 | L7: =K7/J7 -> 0.14427608
A8: EBITDA margin % | B8: =B7/B2 -> 0.21263835 | I8: =EDATE(I7,1) -> 45931 | J8: =SUMIFS(financialdata[Revenue],financialdata[Date],">="&I8,financialdata[Date],"<"&EDATE('Financial Analysis'!I8,1)) -> 2366948.1 | K8: =SUMIFS(financialdata[Net_Profit],financialdata[Date],">="&'Financial Analysis'!I8,financialdata[Date],"<"&EDATE('Financial Analysis'!I8,1)) -> 403834.64 | L8: =K8/J8 -> 0.17061407
A9: Net profit | B9: =SUM(financialdata[Net_Profit]) -> 4098359.8 | I9: =EDATE(I8,1) -> 45962 | J9: =SUMIFS(financialdata[Revenue],financialdata[Date],">="&I9,financialdata[Date],"<"&EDATE('Financial Analysis'!I9,1)) -> 2520853.2 | K9: =SUMIFS(financialdata[Net_Profit],financialdata[Date],">="&'Financial Analysis'!I9,financialdata[Date],"<"&EDATE('Financial Analysis'!I9,1)) -> 424577.23 | L9: =K9/J9 -> 0.168426
A10: Net profit margin % | B10: =B9/B2 -> 0.16700849 | I10: =EDATE(I9,1) -> 45992 | J10: =SUMIFS(financialdata[Revenue],financialdata[Date],">="&I10,financialdata[Date],"<"&EDATE('Financial Analysis'!I10,1)) -> 2097336.4 | K10: =SUMIFS(financialdata[Net_Profit],financialdata[Date],">="&'Financial Analysis'!I10,financialdata[Date],"<"&EDATE('Financial Analysis'!I10,1)) -> 369886.04 | L10: =K10/J10 -> 0.1763599
I11: =EDATE(I10,1) -> 46023 | J11: =SUMIFS(financialdata[Revenue],financialdata[Date],">="&I11,financialdata[Date],"<"&EDATE('Financial Analysis'!I11,1)) -> 1848228.8 | K11: =SUMIFS(financialdata[Net_Profit],financialdata[Date],">="&'Financial Analysis'!I11,financialdata[Date],"<"&EDATE('Financial Analysis'!I11,1)) -> 322667.64 | L11: =K11/J11 -> 0.17458209
I12: =EDATE(I11,1) -> 46054 | J12: =SUMIFS(financialdata[Revenue],financialdata[Date],">="&I12,financialdata[Date],"<"&EDATE('Financial Analysis'!I12,1)) -> 1814475.4 | K12: =SUMIFS(financialdata[Net_Profit],financialdata[Date],">="&'Financial Analysis'!I12,financialdata[Date],"<"&EDATE('Financial Analysis'!I12,1)) -> 301605.49 | L12: =K12/J12 -> 0.16622187
I13: =EDATE(I12,1) -> 46082 | J13: =SUMIFS(financialdata[Revenue],financialdata[Date],">="&I13,financialdata[Date],"<"&EDATE('Financial Analysis'!I13,1)) -> 2061969.8 | K13: =SUMIFS(financialdata[Net_Profit],financialdata[Date],">="&'Financial Analysis'!I13,financialdata[Date],"<"&EDATE('Financial Analysis'!I13,1)) -> 347698.6 | L13: =K13/J13 -> 0.16862448
A14: REGION | B14: REVENUE | C14: GROSS PROFIT | D14: NET PROFIT | E14: NET PROFIT MARGIN %
A15: KERALA | B15: =SUMIF(financialdata[Region],A15,financialdata[Revenue]) -> 8225936 | C15: =SUMIF(financialdata[Region],A15,financialdata[Gross_Profit]) -> 2659924.9 | D15: =SUMIF(financialdata[Region],'Financial Analysis'!A15,financialdata[Net_Profit]) -> 1408067.2 | E15: =D15/B15 -> 0.1711741 | I15: MONTH | J15: ACTUAL REVENUE | K15: BUDGET REVENUE | L15: REVENUE VARIENCE | M15: REVENUE VARIENCE%
A16: TAMIL NADU | B16: =SUMIF(financialdata[Region],A16,financialdata[Revenue]) -> 6523310.3 | C16: =SUMIF(financialdata[Region],A16,financialdata[Gross_Profit]) -> 2099295.2 | D16: =SUMIF(financialdata[Region],'Financial Analysis'!A16,financialdata[Net_Profit]) -> 1110687.2 | E16: =D16/B16 -> 0.17026435 | I16: 45748 | J16: =J2 -> 1998337.2 | K16: =SUMIFS(financialdata[Budget_Revenue],financialdata[Date],">="&'Financial Analysis'!I16,financialdata[Date],"<"&EDATE('Financial Analysis'!I16,1)) -> 2015678.6 | L16: =J16-K16 -> -17341.4 | M16: =L16/K16 -> -0.0086032565
A17: KARNATAKA | B17: =SUMIF(financialdata[Region],A17,financialdata[Revenue]) -> 5779573.3 | C17: =SUMIF(financialdata[Region],A17,financialdata[Gross_Profit]) -> 1884160.4 | D17: =SUMIF(financialdata[Region],'Financial Analysis'!A17,financialdata[Net_Profit]) -> 1001909.8 | E17: =D17/B17 -> 0.1733536 | I17: =EDATE(I16,1) -> 45778 | J17: =J3 -> 1842819.7 | K17: =SUMIFS(financialdata[Budget_Revenue],financialdata[Date],">="&'Financial Analysis'!I17,financialdata[Date],"<"&EDATE('Financial Analysis'!I17,1)) -> 1859955.8 | L17: =J17-K17 -> -17136.12 | M17: =L17/K17 -> -0.0092131867
A18: MAHARASHTRA | B18: =SUMIF(financialdata[Region],A18,financialdata[Revenue]) -> 4011009 | C18: =SUMIF(financialdata[Region],A18,financialdata[Gross_Profit]) -> 1227238 | D18: =SUMIF(financialdata[Region],'Financial Analysis'!A18,financialdata[Net_Profit]) -> 577695.61 | E18: =D18/B18 -> 0.1440275 | I18: =EDATE(I17,1) -> 45809 | J18: =J4 -> 1890702 | K18: =SUMIFS(financialdata[Budget_Revenue],financialdata[Date],">="&'Financial Analysis'!I18,financialdata[Date],"<"&EDATE('Financial Analysis'!I18,1)) -> 1913392.4 | L18: =J18-K18 -> -22690.42 | M18: =L18/K18 -> -0.011858739
I19: =EDATE(I18,1) -> 45839 | J19: =J5 -> 1921643 | K19: =SUMIFS(financialdata[Budget_Revenue],financialdata[Date],">="&'Financial Analysis'!I19,financialdata[Date],"<"&EDATE('Financial Analysis'!I19,1)) -> 1939384.9 | L19: =J19-K19 -> -17741.89 | M19: =L19/K19 -> -0.0091482048
A20: REGION | B20: CATEGORY | C20: REVENUE | D20: GROSS PROFIT | E20: NET PROFIT | F20: NET PROFIT MARGIN % | I20: =EDATE(I19,1) -> 45870 | J20: =J6 -> 2156635.5 | K20: =SUMIFS(financialdata[Budget_Revenue],financialdata[Date],">="&'Financial Analysis'!I20,financialdata[Date],"<"&EDATE('Financial Analysis'!I20,1)) -> 2174265.8 | L20: =J20-K20 -> -17630.23 | M20: =L20/K20 -> -0.0081085902
A21: MAHARASHTRA | B21: Home care | C21: =SUMIFS(financialdata[Revenue],financialdata[Region],A21,financialdata[Category],'Financial Analysis'!B21) -> 729263.75 | D21: =SUMIFS(financialdata[Gross_Profit],financialdata[Region],'Financial Analysis'!A21,financialdata[Category],'Financial Analysis'!B21) -> 275756.87 | E21: =SUMIFS(financialdata[Net_Profit],financialdata[Region],'Financial Analysis'!A21,financialdata[Category],'Financial Analysis'!B21) -> 146949.03 | F21: =E21/C21 -> 0.20150327 | I21: =EDATE(I20,1) -> 45901 | J21: =J7 -> 2019879.5 | K21: =SUMIFS(financialdata[Budget_Revenue],financialdata[Date],">="&'Financial Analysis'!I21,financialdata[Date],"<"&EDATE('Financial Analysis'!I21,1)) -> 2041973.1 | L21: =J21-K21 -> -22093.55 | M21: =L21/K21 -> -0.010819707
A22: MAHARASHTRA | B22: Personal care | C22: =SUMIFS(financialdata[Revenue],financialdata[Region],A22,financialdata[Category],'Financial Analysis'!B22) -> 745309.22 | D22: =SUMIFS(financialdata[Gross_Profit],financialdata[Region],'Financial Analysis'!A22,financialdata[Category],'Financial Analysis'!B22) -> 312542.85 | E22: =SUMIFS(financialdata[Net_Profit],financialdata[Region],'Financial Analysis'!A22,financialdata[Category],'Financial Analysis'!B22) -> 172506.51 | F22: =E22/C22 -> 0.23145629 | I22: =EDATE(I21,1) -> 45931 | J22: =J8 -> 2366948.1 | K22: =SUMIFS(financialdata[Budget_Revenue],financialdata[Date],">="&'Financial Analysis'!I22,financialdata[Date],"<"&EDATE('Financial Analysis'!I22,1)) -> 2404926.3 | L22: =J22-K22 -> -37978.16 | M22: =L22/K22 -> -0.015791819
A23: MAHARASHTRA | B23: Food & Beverages | C23: =SUMIFS(financialdata[Revenue],financialdata[Region],A23,financialdata[Category],'Financial Analysis'!B23) -> 572934.01 | D23: =SUMIFS(financialdata[Gross_Profit],financialdata[Region],'Financial Analysis'!A23,financialdata[Category],'Financial Analysis'!B23) -> 173756.94 | E23: =SUMIFS(financialdata[Net_Profit],financialdata[Region],'Financial Analysis'!A23,financialdata[Category],'Financial Analysis'!B23) -> 80796.15 | F23: =E23/C23 -> 0.14102174 | I23: =EDATE(I22,1) -> 45962 | J23: =J9 -> 2520853.2 | K23: =SUMIFS(financialdata[Budget_Revenue],financialdata[Date],">="&'Financial Analysis'!I23,financialdata[Date],"<"&EDATE('Financial Analysis'!I23,1)) -> 2543785.6 | L23: =J23-K23 -> -22932.47 | M23: =L23/K23 -> -0.0090150953
A24: MAHARASHTRA | B24: Electronics Accessories | C24: =SUMIFS(financialdata[Revenue],financialdata[Region],A24,financialdata[Category],'Financial Analysis'!B24) -> 1963502 | D24: =SUMIFS(financialdata[Gross_Profit],financialdata[Region],'Financial Analysis'!A24,financialdata[Category],'Financial Analysis'!B24) -> 465181.31 | E24: =SUMIFS(financialdata[Net_Profit],financialdata[Region],'Financial Analysis'!A24,financialdata[Category],'Financial Analysis'!B24) -> 177443.92 | F24: =E24/C24 -> 0.090371142 | I24: =EDATE(I23,1) -> 45992 | J24: =J10 -> 2097336.4 | K24: =SUMIFS(financialdata[Budget_Revenue],financialdata[Date],">="&'Financial Analysis'!I24,financialdata[Date],"<"&EDATE('Financial Analysis'!I24,1)) -> 2110527.7 | L24: =J24-K24 -> -13191.31 | M24: =L24/K24 -> -0.0062502425
I25: =EDATE(I24,1) -> 46023 | J25: =J11 -> 1848228.8 | K25: =SUMIFS(financialdata[Budget_Revenue],financialdata[Date],">="&'Financial Analysis'!I25,financialdata[Date],"<"&EDATE('Financial Analysis'!I25,1)) -> 1865085.2 | L25: =J25-K25 -> -16856.39 | M25: =L25/K25 -> -0.0090378659
A26: Key Findings | I26: =EDATE(I25,1) -> 46054 | J26: =J12 -> 1814475.4 | K26: =SUMIFS(financialdata[Budget_Revenue],financialdata[Date],">="&'Financial Analysis'!I26,financialdata[Date],"<"&EDATE('Financial Analysis'!I26,1)) -> 1832052.8 | L26: =J26-K26 -> -17577.38 | M26: =L26/K26 -> -0.0095943632
A27: Electronics Accessories has the lowest net profit margin in Maharashtra at 9.04%, contributing to the region's lower overall profitability. | I27: =EDATE(I26,1) -> 46082 | J27: =J13 -> 2061969.8 | K27: =SUMIFS(financialdata[Budget_Revenue],financialdata[Date],">="&'Financial Analysis'!I27,financialdata[Date],"<"&EDATE('Financial Analysis'!I27,1)) -> 2070490.3 | L27: =J27-K27 -> -8520.44 | M27: =L27/K27 -> -0.0041151799
A29: REGION | B29: CATEGORY | C29: PRODUCT | D29: REVENUE | E29: GROSS PROFIT | F29: NET PROFIT | G29: NET MARGIN % | I29: MONTH | J29: ACTUAL EXPENSES | K29: BUDGET EXPENSES | L29: EXPENSES VARIANCES | M29: EXPENSES VARIENCES %
A30: Maharashtra | B30: Electronics Accessories | C30: USB Cable | D30: =SUMIFS(financialdata[Revenue],financialdata[Region],'Financial Analysis'!A30,financialdata[Category],'Financial Analysis'!B30,financialdata[Product],'Financial Analysis'!C30) -> 229491.84 | E30: =SUMIFS(financialdata[Gross_Profit],financialdata[Region],'Financial Analysis'!A30,financialdata[Category],'Financial Analysis'!B30,financialdata[Product],'Financial Analysis'!C30) -> 53862.6 | F30: =SUMIFS(financialdata[Net_Profit],financialdata[Region],'Financial Analysis'!A30,financialdata[Category],'Financial Analysis'!B30,financialdata[Product],'Financial Analysis'!C30) -> 20065.04 | G30: =F30/D30 -> 0.087432477 | I30: 45748 | J30: =SUMIFS(financialdata[Operating_Expense],financialdata[Date],">="&'Financial Analysis'!I30,financialdata[Date],"<"&EDATE('Financial Analysis'!I30,1)) -> 215114.48 | K30: =SUMIFS(financialdata[Budget_Expense],financialdata[Date],">="&'Financial Analysis'!I30,financialdata[Date],"<"&EDATE('Financial Analysis'!I30,1)) -> 217112.29 | L30: =J30-K30 -> -1997.81 | M30: =L30/K30 -> -0.0092017361
A31: Maharashtra | B31: Electronics Accessories | C31: Power Bank | D31: =SUMIFS(financialdata[Revenue],financialdata[Region],'Financial Analysis'!A31,financialdata[Category],'Financial Analysis'!B31,financialdata[Product],'Financial Analysis'!C31) -> 734020.51 | E31: =SUMIFS(financialdata[Gross_Profit],financialdata[Region],'Financial Analysis'!A31,financialdata[Category],'Financial Analysis'!B31,financialdata[Product],'Financial Analysis'!C31) -> 176412.52 | F31: =SUMIFS(financialdata[Net_Profit],financialdata[Region],'Financial Analysis'!A31,financialdata[Category],'Financial Analysis'!B31,financialdata[Product],'Financial Analysis'!C31) -> 69455.46 | G31: =F31/D31 -> 0.094623323 | I31: =EDATE(I30,1) -> 45778 | J31: =SUMIFS(financialdata[Operating_Expense],financialdata[Date],">="&'Financial Analysis'!I31,financialdata[Date],"<"&EDATE('Financial Analysis'!I31,1)) -> 197222.42 | K31: =SUMIFS(financialdata[Budget_Expense],financialdata[Date],">="&'Financial Analysis'!I31,financialdata[Date],"<"&EDATE('Financial Analysis'!I31,1)) -> 198427.02 | L31: =J31-K31 -> -1204.6 | M31: =L31/K31 -> -0.0060707458
A32: Maharashtra | B32: Electronics Accessories | C32: Wireless Mouse | D32: =SUMIFS(financialdata[Revenue],financialdata[Region],'Financial Analysis'!A32,financialdata[Category],'Financial Analysis'!B32,financialdata[Product],'Financial Analysis'!C32) -> 587980.14 | E32: =SUMIFS(financialdata[Gross_Profit],financialdata[Region],'Financial Analysis'!A32,financialdata[Category],'Financial Analysis'!B32,financialdata[Product],'Financial Analysis'!C32) -> 137037.11 | F32: =SUMIFS(financialdata[Net_Profit],financialdata[Region],'Financial Analysis'!A32,financialdata[Category],'Financial Analysis'!B32,financialdata[Product],'Financial Analysis'!C32) -> 50876.87 | G32: =F32/D32 -> 0.086528212 | I32: =EDATE(I31,1) -> 45809 | J32: =SUMIFS(financialdata[Operating_Expense],financialdata[Date],">="&'Financial Analysis'!I32,financialdata[Date],"<"&EDATE('Financial Analysis'!I32,1)) -> 205292.54 | K32: =SUMIFS(financialdata[Budget_Expense],financialdata[Date],">="&'Financial Analysis'!I32,financialdata[Date],"<"&EDATE('Financial Analysis'!I32,1)) -> 206821.79 | L32: =J32-K32 -> -1529.25 | M32: =L32/K32 -> -0.0073940468
A33: Maharashtra | B33: Electronics Accessories | C33: Phone charger | D33: =SUMIFS(financialdata[Revenue],financialdata[Region],'Financial Analysis'!A33,financialdata[Category],'Financial Analysis'!B33,financialdata[Product],'Financial Analysis'!C33) -> 412009.53 | E33: =SUMIFS(financialdata[Gross_Profit],financialdata[Region],'Financial Analysis'!A33,financialdata[Category],'Financial Analysis'!B33,financialdata[Product],'Financial Analysis'!C33) -> 97869.08 | F33: =SUMIFS(financialdata[Net_Profit],financialdata[Region],'Financial Analysis'!A33,financialdata[Category],'Financial Analysis'!B33,financialdata[Product],'Financial Analysis'!C33) -> 37046.55 | G33: =F33/D33 -> 0.089916731 | I33: =EDATE(I32,1) -> 45839 | J33: =SUMIFS(financialdata[Operating_Expense],financialdata[Date],">="&'Financial Analysis'!I33,financialdata[Date],"<"&EDATE('Financial Analysis'!I33,1)) -> 209199.26 | K33: =SUMIFS(financialdata[Budget_Expense],financialdata[Date],">="&'Financial Analysis'!I33,financialdata[Date],"<"&EDATE('Financial Analysis'!I33,1)) -> 212003.77 | L33: =J33-K33 -> -2804.51 | M33: =L33/K33 -> -0.013228586
I34: =EDATE(I33,1) -> 45870 | J34: =SUMIFS(financialdata[Operating_Expense],financialdata[Date],">="&'Financial Analysis'!I34,financialdata[Date],"<"&EDATE('Financial Analysis'!I34,1)) -> 233352.05 | K34: =SUMIFS(financialdata[Budget_Expense],financialdata[Date],">="&'Financial Analysis'!I34,financialdata[Date],"<"&EDATE('Financial Analysis'!I34,1)) -> 235086.96 | L34: =J34-K34 -> -1734.91 | M34: =L34/K34 -> -0.0073798649
I35: =EDATE(I34,1) -> 45901 | J35: =SUMIFS(financialdata[Operating_Expense],financialdata[Date],">="&'Financial Analysis'!I35,financialdata[Date],"<"&EDATE('Financial Analysis'!I35,1)) -> 219853.82 | K35: =SUMIFS(financialdata[Budget_Expense],financialdata[Date],">="&'Financial Analysis'!I35,financialdata[Date],"<"&EDATE('Financial Analysis'!I35,1)) -> 222242.26 | L35: =J35-K35 -> -2388.44 | M35: =L35/K35 -> -0.010747011
I36: =EDATE(I35,1) -> 45931 | J36: =SUMIFS(financialdata[Operating_Expense],financialdata[Date],">="&'Financial Analysis'!I36,financialdata[Date],"<"&EDATE('Financial Analysis'!I36,1)) -> 255711.97 | K36: =SUMIFS(financialdata[Budget_Expense],financialdata[Date],">="&'Financial Analysis'!I36,financialdata[Date],"<"&EDATE('Financial Analysis'!I36,1)) -> 259508.86 | L36: =J36-K36 -> -3796.89 | M36: =L36/K36 -> -0.014631061
I37: =EDATE(I36,1) -> 45962 | J37: =SUMIFS(financialdata[Operating_Expense],financialdata[Date],">="&'Financial Analysis'!I37,financialdata[Date],"<"&EDATE('Financial Analysis'!I37,1)) -> 271522.93 | K37: =SUMIFS(financialdata[Budget_Expense],financialdata[Date],">="&'Financial Analysis'!I37,financialdata[Date],"<"&EDATE('Financial Analysis'!I37,1)) -> 275039.87 | L37: =J37-K37 -> -3516.94 | M37: =L37/K37 -> -0.012787019
I38: =EDATE(I37,1) -> 45992 | J38: =SUMIFS(financialdata[Operating_Expense],financialdata[Date],">="&'Financial Analysis'!I38,financialdata[Date],"<"&EDATE('Financial Analysis'!I38,1)) -> 225843.97 | K38: =SUMIFS(financialdata[Budget_Expense],financialdata[Date],">="&'Financial Analysis'!I38,financialdata[Date],"<"&EDATE('Financial Analysis'!I38,1)) -> 228055.04 | L38: =J38-K38 -> -2211.07 | M38: =L38/K38 -> -0.009695335
I39: =EDATE(I38,1) -> 46023 | J39: =SUMIFS(financialdata[Operating_Expense],financialdata[Date],">="&'Financial Analysis'!I39,financialdata[Date],"<"&EDATE('Financial Analysis'!I39,1)) -> 198289.71 | K39: =SUMIFS(financialdata[Budget_Expense],financialdata[Date],">="&'Financial Analysis'!I39,financialdata[Date],"<"&EDATE('Financial Analysis'!I39,1)) -> 200856.78 | L39: =J39-K39 -> -2567.07 | M39: =L39/K39 -> -0.012780599
I40: =EDATE(I39,1) -> 46054 | J40: =SUMIFS(financialdata[Operating_Expense],financialdata[Date],">="&'Financial Analysis'!I40,financialdata[Date],"<"&EDATE('Financial Analysis'!I40,1)) -> 198985.21 | K40: =SUMIFS(financialdata[Budget_Expense],financialdata[Date],">="&'Financial Analysis'!I40,financialdata[Date],"<"&EDATE('Financial Analysis'!I40,1)) -> 201641.02 | L40: =J40-K40 -> -2655.81 | M40: =L40/K40 -> -0.013170981
I41: =EDATE(I40,1) -> 46082 | J41: =SUMIFS(financialdata[Operating_Expense],financialdata[Date],">="&'Financial Analysis'!I41,financialdata[Date],"<"&EDATE('Financial Analysis'!I41,1)) -> 222121.14 | K41: =SUMIFS(financialdata[Budget_Expense],financialdata[Date],">="&'Financial Analysis'!I41,financialdata[Date],"<"&EDATE('Financial Analysis'!I41,1)) -> 224742.33 | L41: =J41-K41 -> -2621.19 | M41: =L41/K41 -> -0.01166309
...

Sheet Data_Dictionary
A1: Field | B1: Description
A2: Invoice_ID | B2: Unique invoice identifier
A3: Date | B3: Transaction date
A4: Customer | B4: Customer
A5: Region | B5: Sales region
A6: Category | B6: Product category
A7: Product | B7: Product
A8: Quantity | B8: Units sold
A9: Unit_Price | B9: Selling price per unit
A10: Revenue | B10: Sales revenue
A11: COGS | B11: Cost of goods sold
A12: Gross_Profit | B12: Revenue minus COGS
... A18: Budget_Expense | B18: Budgeted operating expense
